Workbook
Name TypesList: OFFSET(Backend!$A$2,0,0,COUNTA(Backend!$A:$A)-1,1)

Sheet Dashboard
A1: ميزانيتي الشهرية
A2: ■ جداول إدخال | I2: ■ جداول قرار ونتائج
A3: الدخل | I3: الملخص
A4: المصدر | B4: المبلغ | I4: البند | J4: المبلغ | K4: % من الدخل
I5: إجمالي الدخل | J5: =B11 -> 0 | K5: =IFERROR(J5/$J$5,0) -> 0
I6: إجمالي المصروفات | J6: =F50 -> 0 | K6: =IFERROR(J6/$J$5,0) -> 0
I7: منها: الأقساط | J7: =SUMIF(B15:B49,"دين/أقساط",F15:F49) -> 0 | K7: =IFERROR(J7/$J$5,0) -> 0
I8: منها: الكماليات | J8: =SUMIF(B15:B49,"كمالي",F15:F49) -> 0 | K8: =IFERROR(J8/$J$5,0) -> 0
I9: منها: الأساسيات | J9: =SUMIF(B15:B49,"أساسي",F15:F49) -> 0 | K9: =IFERROR(J9/$J$5,0) -> 0
A10: سحب من المدخرات | I10: الصافي (الفائض) | J10: =J5-J6 -> 0 | K10: =IFERROR(J10/$J$5,0) -> 0
A11: إجمالي الدخل | B11: =SUM(B5:B10) -> 0 | I11: الحالة | J11: =IF(J10<0,"🔴 خطر - عجز",IF(J10-B58<0,"🟠 مزنوق - السحب من المدخرات غطّى العجز",IF(AND(K7>Backend!D6,K8>Backend!D7),"🟠 انتبه - أقساط وكماليات مرتفعة",IF(K7>Backend!D6,"🟠 انتبه - أقساط مرتفعة",IF(K8>Backend!D7,"🟠 انتبه - كماليات مرتفعة",IF(J27>0,"🟡 جيد - كمّل صندوق الطوارئ",IF(K10>=Backend!D4,"🟢 ممتاز",IF(K10>=Backend!D5,"🟡 جيد","🟠 مقبول - فائضك قليل")))))))) -> 🟠 مقبول - فائضك قليل
A13: المصروفات والالتزامات | I13: الاقتراحات الشهرية
A14: البند | B14: النوع | C14: كاش | D14: تقسيط (إجمالي) | E14: عدد الدفعات | F14: الشهري | G14: حالة الدفع | I14: البند | J14: المبلغ | K14: % من الدخل
F15: =IF(E15>0,C15+D15/E15,C15+D15) -> 0 | I15: 1) لصندوق الطوارئ | J15: =Backend!D16 -> 0 | K15: =IFERROR(J15/$J$5,0) -> 0
F16: =IF(E16>0,C16+D16/E16,C16+D16) -> 0 | I16: 2) للادخار والأهداف | J16: =Backend!D17 -> 0 | K16: =IFERROR(J16/$J$5,0) -> 0
F17: =IF(E17>0,C17+D17/E17,C17+D17) -> 0 | I17: 3) الصرف الآمن - اصرف وانت مطمن | J17: =Backend!D18 -> 0 | K17: =IFERROR(J17/$J$5,0) -> 0
F18: =IF(E18>0,C18+D18/E18,C18+D18) -> 0 | I18: الصرف الآمن يومياً | J18: =Backend!D19 -> 0
F19: =IF(E19>0,C19+D19/E19,C19+D19) -> 0 | I19: الصرف الآمن أسبوعياً | J19: =Backend!D20 -> 0
F20: =IF(E20>0,C20+D20/E20,C20+D20) -> 0 | I20: ↩️ رجّع للمدخرات (سداد السحب) | J20: =Backend!D22 -> 0 | K20: =IFERROR(J20/$J$5,0) -> 0
F21: =IF(E21>0,C21+D21/E21,C21+D21) -> 0 | I21: صندوق الطوارئ
F22: =IF(E22>0,C22+D22/E22,C22+D22) -> 0 | I22: مبلغ الطوارئ الحالي
F23: =IF(E23>0,C23+D23/E23,C23+D23) -> 0 | I23: إضافة من جدول المصروفات | J23: =SUMIF(B15:B49,"طوارئ",F15:F49) -> 0
F24: =IF(E24>0,C24+D24/E24,C24+D24) -> 0 | I24: مبلغ الطوارئ بعد الإضافة | J24: =J22+J23 -> 0
F25: =IF(E25>0,C25+D25/E25,C25+D25) -> 0 | I25: الحد الأدنى للطوارئ
F26: =IF(E26>0,C26+D26/E26,C26+D26) -> 0 | I26: مرجع: (الأساسي + الأقساط) × 3 أشهر | J26: =3*(SUMIF(B15:B49,"أساسي",F15:F49)+SUMIF(B15:B49,"دين/أقساط",F15:F49))*1.25 -> 0
F27: =IF(E27>0,C27+D27/E27,C27+D27) -> 0 | I27: المتبقي لاكتمال الطوارئ | J27: =MAX(0,J25-J24) -> 0
F28: =IF(E28>0,C28+D28/E28,C28+D28) -> 0 | I28: حالة الطوارئ | J28: =IF(J27=0,"✅ مكتمل","⚠️ غير مكتمل") -> ✅ مكتمل
F29: =IF(E29>0,C29+D29/E29,C29+D29) -> 0 | I29: أشهر متوقعة للاكتمال في حال التقيد بالمقترح | J29: =IF(J27=0,0,IFERROR(ROUNDUP(MAX(0,J25-J22)/(Backend!D16+J23),0),"-")) -> 0
F30: =IF(E30>0,C30+D30/E30,C30+D30) -> 0
F31: =IF(E31>0,C31+D31/E31,C31+D31) -> 0 | I31: ⚠️ التحذيرات
F32: =IF(E32>0,C32+D32/E32,C32+D32) -> 0 | I32: التحذير | J32: الحالة | K32: التفاصيل
F33: =IF(E33>0,C33+D33/E33,C33+D33) -> 0 | I33: عجز في الميزانية | J33: =IF(J10<0,"⚠️ نشط","✅ تمام") -> ✅ تمام | K33: =IF(J10<0,"عجز "&TEXT(-J10,"#,##0")&" ر.س حتى بعد السحب","")
F34: =IF(E34>0,C34+D34/E34,C34+D34) -> 0 | I34: مزنوق - بتصرف من المدخرات | J34: =IF(AND(J10>=0,J10-B58<0),"⚠️ نشط","✅ تمام") -> ✅ تمام | K34: =IF(AND(J10>=0,J10-B58<0),"السحب غطّى عجز "&TEXT(B58-J10,"#,##0")&" ر.س","")
F35: =IF(E35>0,C35+D35/E35,C35+D35) -> 0 | I35: السحب أكبر من المدخر المتاح | J35: =IF(B58>B56+B57,"⚠️ نشط","✅ تمام") -> ✅ تمام | K35: =IF(B58>B56+B57,"سحبت "&TEXT(B58,"#,##0")&" والمتاح "&TEXT(B56+B57,"#,##0")&" ر.س","")
F36: =IF(E36>0,C36+D36/E36,C36+D36) -> 0 | I36: أقساط مرتفعة | J36: =IF(K7>Backend!D6,"⚠️ نشط","✅ تمام") -> ✅ تمام | K36: =IF(K7>Backend!D6,TEXT(K7,"0.0%")&" (الحد "&TEXT(Backend!D6,"0%")&")","")
F37: =IF(E37>0,C37+D37/E37,C37+D37) -> 0 | I37: كماليات مرتفعة | J37: =IF(K8>Backend!D7,"⚠️ نشط","✅ تمام") -> ✅ تمام | K37: =IF(K8>Backend!D7,TEXT(K8,"0.0%")&" (الحد "&TEXT(Backend!D7,"0%")&")","")
F38: =IF(E38>0,C38+D38/E38,C38+D38) -> 0 | I38: صندوق الطوارئ ناقص | J38: =IF(J27>0,"⚠️ نشط","✅ تمام") -> ✅ تمام | K38: =IF(J27>0,"ناقص "&TEXT(J27,"#,##0")&" ر.س","")
F39: =IF(E39>0,C39+D39/E39,C39+D39) -> 0 | I39: الفائض قليل | J39: =IF(AND(J10>=0,K10<Backend!D5),"⚠️ نشط","✅ تمام") -> ⚠️ نشط | K39: =IF(AND(J10>=0,K10<Backend!D5),TEXT(K10,"0.0%")&" (الأدنى "&TEXT(Backend!D5,"0%")&")","") -> 0.0% (الأدنى 10%)
F40: =IF(E40>0,C40+D40/E40,C40+D40) -> 0 | I40: الموزع على الأهداف أكبر من المتوفر | J40: =IF(B61<0,"⚠️ نشط","✅ تمام") -> ✅ تمام | K40: =IF(B61<0,"زيادة "&TEXT(-B61,"#,##0")&" ر.س","")
F41: =IF(E41>0,C41+D41/E41,C41+D41) -> 0 | I41: لازم ترجّع فلوس للمدخرات | J41: =IF(J20>0,"⚠️ نشط","✅ تمام") -> ✅ تمام | K41: =IF(J20>0,"رجّع "&TEXT(J20,"#,##0")&" ر.س","")
...

Sheet Backend
A1: انواع المصروفات | C1: أضف أي نوع جديد تحت قائمة الأنواع (عمود A) وسيظهر تلقائياً ←
A2: طوارئ
A3: ادخار | C3: معايير التقييم | G3: بيانات الرسوم البيانية (تلقائي)
A4: كمالي | C4: ادخار ممتاز إذا ≥ | D4: 0.2 | G4: البند | H4: المبلغ | I4: النسبة
A5: دين/أقساط | C5: ادخار جيد إذا ≥ | D5: 0.1 | G5: =A2 -> طوارئ | H5: =SUMIF(Dashboard!$B$15:$B$49,G5,Dashboard!$F$15:$F$49) -> 0 | I5: =IFERROR(H5/Dashboard!$J$5,0) -> 0
A6: أساسي | C6: الحد الآمن للأقساط ≤ | D6: 0.33 | G6: =A3 -> ادخار | H6: =SUMIF(Dashboard!$B$15:$B$49,G6,Dashboard!$F$15:$F$49) -> 0 | I6: =IFERROR(H6/Dashboard!$J$5,0) -> 0
A7: العطاء والمساندة | C7: الحد المقترح للكماليات ≤ | D7: 0.3 | G7: =A4 -> كمالي | H7: =SUMIF(Dashboard!$B$15:$B$49,G7,Dashboard!$F$15:$F$49) -> 0 | I7: =IFERROR(H7/Dashboard!$J$5,0) -> 0
A8: تحويل خارجي | C8: نسبة الاستقطاع للطوارئ من الصافي | D8: 0.3 | G8: =A5 -> دين/أقساط | H8: =SUMIF(Dashboard!$B$15:$B$49,G8,Dashboard!$F$15:$F$49) -> 0 | I8: =IFERROR(H8/Dashboard!$J$5,0) -> 0
A9: الاستثمار | G9: =A6 -> أساسي | H9: =SUMIF(Dashboard!$B$15:$B$49,G9,Dashboard!$F$15:$F$49) -> 0 | I9: =IFERROR(H9/Dashboard!$J$5,0) -> 0
C10: خطة توزيع الصافي الشهري | G10: =A7 -> العطاء والمساندة | H10: =SUMIF(Dashboard!$B$15:$B$49,G10,Dashboard!$F$15:$F$49) -> 0 | I10: =IFERROR(H10/Dashboard!$J$5,0) -> 0
C11: % ادخار من الباقي (طوارئ غير مكتمل) | D11: 0.2 | G11: =A8 -> تحويل خارجي | H11: =SUMIF(Dashboard!$B$15:$B$49,G11,Dashboard!$F$15:$F$49) -> 0 | I11: =IFERROR(H11/Dashboard!$J$5,0) -> 0
C12: % ادخار من الباقي (طوارئ مكتمل) | D12: 0.5 | G12: =A9 -> الاستثمار | H12: =SUMIF(Dashboard!$B$15:$B$49,G12,Dashboard!$F$15:$F$49) -> 0 | I12: =IFERROR(H12/Dashboard!$J$5,0) -> 0
G13: الفائض (الصافي) | H13: =MAX(0,Dashboard!J10) -> 0 | I13: =IFERROR(H13/Dashboard!$J$5,0) -> 0
C14: البند | D14: المبلغ | E14: % من الصافي
C15: الصافي المتاح (بعد المصروفات وبدون السحب) | D15: =MAX(0,Dashboard!J10-Dashboard!B58) -> 0 | E15: =IFERROR(D15/$D$28,0) -> 0
C16: 1) لصندوق الطوارئ | D16: =MIN(MAX(0,D30-D31),D15) -> 0 | E16: =IFERROR(D16/$D$28,0) -> 0
C17: 2) للادخار والأهداف | D17: =MIN(MAX(0,D33-D34),D15-D16) -> 0 | E17: =IFERROR(D17/$D$28,0) -> 0
C18: 3) الصرف الآمن - اصرف وانت مطمن | D18: =D15-D16-D17 -> 0 | E18: =IFERROR(D18/$D$28,0) -> 0
C19: الصرف الآمن يومياً | D19: =D18/30 -> 0
C20: الصرف الآمن أسبوعياً | D20: =D18/30*7 -> 0
C21: الصرف الآمن % من الدخل | D21: =IFERROR(D18/Dashboard!J5,0) -> 0
C22: ↩️ رجّع للمدخرات (الجزء اللي ما اتصرفش من السحب) | D22: =MIN(Dashboard!B58,MAX(0,Dashboard!J10)) -> 0
C23: التقدم | D23: المتوفر | E23: المتبقي
C24: صندوق الطوارئ | D24: =MIN(Dashboard!J24,Dashboard!J25) -> 0 | E24: =Dashboard!J27 -> 0
C25: أهداف الادخار | D25: =Dashboard!B60 -> 0 | E25: =Dashboard!D75 -> 0
C27: تفاصيل حساب الاقتراحات
C28: الأساس: الصافي قبل الادخار والطوارئ | D28: =MAX(0,Dashboard!J10-Dashboard!B58+Dashboard!J23+Dashboard!B57) -> 0
C29: الطوارئ: المتبقي قبل جدول المصروفات | D29: =MAX(0,Dashboard!J25-Dashboard!J22) -> 0
C30: الطوارئ: المستهدف (الأساس × النسبة) | D30: =MIN(D29,D28*D8) -> 0
C31: الطوارئ: المحطوط في جدول المصروفات | D31: =Dashboard!J23 -> 0
C32: الادخار: النسبة المطبقة | D32: =IF(D29=0,D12,D11) -> 0.5
C33: الادخار: المستهدف (أساس الادخار × النسبة) | D33: =D28*D32 -> 0
C34: الادخار: المحطوط في جدول المصروفات | D34: =Dashboard!B57 -> 0
C37: توزيع المدخر على الأهداف (الأولوية % من المدخر المتاح بعد خصم اليدوي)
C38: الهدف | D38: الأولوية الفعلية | E38: التوزيع - جولة 1 | F38: وزن جولة 2 (غير مكتمل) | G38: التوزيع - جولة 2 | H38: اقتراح التوزيع | I38: وزن الشهري (باقي له مبلغ) | J38: المقترح شهرياً
C39: =IF(Dashboard!A65="","",Dashboard!A65) | D39: =IF(OR(N(Dashboard!B65)<=0,Dashboard!E65<>""),0,IF(Dashboard!C65="",IFERROR(MAX(0,1-SUMIFS(Dashboard!$C$65:$C$74,Dashboard!$E$65:$E$74,""))/COUNTIFS(Dashboard!$B$65:$B$74,">0",Dashboard!$C$65:$C$74,"",Dashboard!$E$65:$E$74,""),0),Dashboard!C65)) -> 0 | E39: =IFERROR(MIN(N(Dashboard!B65),$D$51*D39/MAX(1,SUM($D$39:$D$48))),0) -> 0 | F39: =IF(E39<N(Dashboard!B65),D39,0) -> 0 | G39: =IFERROR(MIN(N(Dashboard!B65)-E39,($D$51*MIN(1,SUM($D$39:$D$48))-SUM($E$39:$E$48))*F39/SUM($F$39:$F$48)),0) -> 0 | H39: =E39+G39 -> 0 | I39: =IF(Dashboard!F65>0,D39,0) -> 0 | J39: =IFERROR(MIN(Dashboard!F65,$D$50*IF(SUM($I$39:$I$48)>0,I39/SUM($I$39:$I$48),(Dashboard!F65>0)/COUNTIF(Dashboard!$F$65:$F$74,">0"))),0) -> 0
C40: =IF(Dashboard!A66="","",Dashboard!A66) | D40: =IF(OR(N(Dashboard!B66)<=0,Dashboard!E66<>""),0,IF(Dashboard!C66="",IFERROR(MAX(0,1-SUMIFS(Dashboard!$C$65:$C$74,Dashboard!$E$65:$E$74,""))/COUNTIFS(Dashboard!$B$65:$B$74,">0",Dashboard!$C$65:$C$74,"",Dashboard!$E$65:$E$74,""),0),Dashboard!C66)) -> 0 | E40: =IFERROR(MIN(N(Dashboard!B66),$D$51*D40/MAX(1,SUM($D$39:$D$48))),0) -> 0 | F40: =IF(E40<N(Dashboard!B66),D40,0) -> 0 | G40: =IFERROR(MIN(N(Dashboard!B66)-E40,($D$51*MIN(1,SUM($D$39:$D$48))-SUM($E$39:$E$48))*F40/SUM($F$39:$F$48)),0) -> 0 | H40: =E40+G40 -> 0 | I40: =IF(Dashboard!F66>0,D40,0) -> 0 | J40: =IFERROR(MIN(Dashboard!F66,$D$50*IF(SUM($I$39:$I$48)>0,I40/SUM($I$39:$I$48),(Dashboard!F66>0)/COUNTIF(Dashboard!$F$65:$F$74,">0"))),0) -> 0
C41: =IF(Dashboard!A67="","",Dashboard!A67) | D41: =IF(OR(N(Dashboard!B67)<=0,Dashboard!E67<>""),0,IF(Dashboard!C67="",IFERROR(MAX(0,1-SUMIFS(Dashboard!$C$65:$C$74,Dashboard!$E$65:$E$74,""))/COUNTIFS(Dashboard!$B$65:$B$74,">0",Dashboard!$C$65:$C$74,"",Dashboard!$E$65:$E$74,""),0),Dashboard!C67)) -> 0 | E41: =IFERROR(MIN(N(Dashboard!B67),$D$51*D41/MAX(1,SUM($D$39:$D$48))),0) -> 0 | F41: =IF(E41<N(Dashboard!B67),D41,0) -> 0 | G41: =IFERROR(MIN(N(Dashboard!B67)-E41,($D$51*MIN(1,SUM($D$39:$D$48))-SUM($E$39:$E$48))*F41/SUM($F$39:$F$48)),0) -> 0 | H41: =E41+G41 -> 0 | I41: =IF(Dashboard!F67>0,D41,0) -> 0 | J41: =IFERROR(MIN(Dashboard!F67,$D$50*IF(SUM($I$39:$I$48)>0,I41/SUM($I$39:$I$48),(Dashboard!F67>0)/COUNTIF(Dashboard!$F$65:$F$74,">0"))),0) -> 0
C42: =IF(Dashboard!A68="","",Dashboard!A68) | D42: =IF(OR(N(Dashboard!B68)<=0,Dashboard!E68<>""),0,IF(Dashboard!C68="",IFERROR(MAX(0,1-SUMIFS(Dashboard!$C$65:$C$74,Dashboard!$E$65:$E$74,""))/COUNTIFS(Dashboard!$B$65:$B$74,">0",Dashboard!$C$65:$C$74,"",Dashboard!$E$65:$E$74,""),0),Dashboard!C68)) -> 0 | E42: =IFERROR(MIN(N(Dashboard!B68),$D$51*D42/MAX(1,SUM($D$39:$D$48))),0) -> 0 | F42: =IF(E42<N(Dashboard!B68),D42,0) -> 0 | G42: =IFERROR(MIN(N(Dashboard!B68)-E42,($D$51*MIN(1,SUM($D$39:$D$48))-SUM($E$39:$E$48))*F42/SUM($F$39:$F$48)),0) -> 0 | H42: =E42+G42 -> 0 | I42: =IF(Dashboard!F68>0,D42,0) -> 0 | J42: =IFERROR(MIN(Dashboard!F68,$D$50*IF(SUM($I$39:$I$48)>0,I42/SUM($I$39:$I$48),(Dashboard!F68>0)/COUNTIF(Dashboard!$F$65:$F$74,">0"))),0) -> 0
C43: =IF(Dashboard!A69="","",Dashboard!A69) | D43: =IF(OR(N(Dashboard!B69)<=0,Dashboard!E69<>""),0,IF(Dashboard!C69="",IFERROR(MAX(0,1-SUMIFS(Dashboard!$C$65:$C$74,Dashboard!$E$65:$E$74,""))/COUNTIFS(Dashboard!$B$65:$B$74,">0",Dashboard!$C$65:$C$74,"",Dashboard!$E$65:$E$74,""),0),Dashboard!C69)) -> 0 | E43: =IFERROR(MIN(N(Dashboard!B69),$D$51*D43/MAX(1,SUM($D$39:$D$48))),0) -> 0 | F43: =IF(E43<N(Dashboard!B69),D43,0) -> 0 | G43: =IFERROR(MIN(N(Dashboard!B69)-E43,($D$51*MIN(1,SUM($D$39:$D$48))-SUM($E$39:$E$48))*F43/SUM($F$39:$F$48)),0) -> 0 | H43: =E43+G43 -> 0 | I43: =IF(Dashboard!F69>0,D43,0) -> 0 | J43: =IFERROR(MIN(Dashboard!F69,$D$50*IF(SUM($I$39:$I$48)>0,I43/SUM($I$39:$I$48),(Dashboard!F69>0)/COUNTIF(Dashboard!$F$65:$F$74,">0"))),0) -> 0
...
